Workbook
Name NativeTimeline_Date___Time: #N/A
Name Slicer_Payment_Method: #N/A
Name Slicer_PSP_Provider: #N/A

Sheet Documentation
A1: 📄 PSP Performance Architecture — Documentation
A2: Payment Service Provider Transaction Analysis · FY2024 · Nikolas Andreou
A4: PROJECT OVERVIEW
A5: Objective | B5: Analyze PSP transaction performance across 5 payment providers, 10 European markets, and 5 payment methods to identify optimization opportunities for conversion rates, revenue, and cost efficiency.
A6: Dataset | B6: 1,000 synthetic transactions spanning January–December 2024, covering SEK, NOK, EUR, GBP, and PLN currencies. All monetary values normalized to EUR for cross-market comparability.
A7: Scope | B7: Conversion rate analysis, revenue & fee benchmarking, geographic performance, decline reason diagnosis, and best-provider-per-market recommendations.
A8: Tools Used | B8: Microsoft Excel — formulas (COUNTIFS, SUMIFS, AVERAGEIFS, VLOOKUP, XLOOKUP, INDEX/MATCH, UNIQUE, SORT, FILTER), pivot tables, conditional formatting, dashboard design. Power Query — used to merge Raw Data (Jan-Jun) and Raw Data (Jul-Dec) into Raw_Data_Combined with FX rate lookups for multi-currency normalization.
A9: DATA DESCRIPTION
A10: Field | B10: Description | C10: Example
A11: Transaction ID | B11: Unique identifier for each transaction | C11: TXN00108
A12: Date & Time | B12: Transaction timestamp (Excel serial date) | C12: 45292.913
A13: GEO | B13: ISO 2-letter country code | C13: SE, NO, ES, FR, GB, PL, NL, IT, CY, DE
A14: Currency | B14: Original transaction currency | C14: SEK, NOK, EUR, GBP, PLN
A15: PSP Provider | B15: Payment service provider processing the transaction | C15: Worldpay, Stripe, Checkout.com, PaySafe, Adyen
A16: Payment Method | B16: Customer payment instrument | C16: Credit Card, Debit Card, E-Wallet, Bank Transfer, Crypto
A17: Amount | B17: Transaction amount in original currency | C17: 4,887.84 NOK
A18: Status | B18: Transaction outcome | C18: Success, Pending, Failed
A19: Decline Reason | B19: Reason for failure (Failed transactions only) | C19: Card Declined, Technical Error, Fraud Suspected, Insufficient Funds, Expired Card
A20: Fee % | B20: Provider fee rate applied to successful transactions | C20: 1.9%, 2.1%, 2.5%, 2.9%, 3.2%
A21: Exchange Rate to EUR | B21: Conversion rate from original currency to EUR | C21: SEK: 0.0874
A22: Fee Amount EUR | B22: Fee in EUR (Amount × Rate × Fee% for Success only) | C22: 10.51
A23: Net Amount EUR | B23: Revenue after fees in EUR (Gross − Fee) | C23: 420.35
A24: Gross Amount EUR | B24: Total in EUR before fees (Amount × Exchange Rate) | C24: 409.85
A25: Month Name | B25: Calendar month derived from Date & Time | C25: January
A26: KEY ASSUMPTIONS & METHODOLOGY
A27: Currency Conversion | B27: All non-EUR amounts converted using fixed mid-market rates sourced from European Central Bank (ECB). Rates represent annual averages for 2024. See "FX Rates" tab for full rate table.
A28: Fee Calculation | B28: Fees are modeled as percentage-based rates only (e.g., 1.9%, 2.1%, 2.5%). In practice, PSP providers often charge a combination of percentage fees and fixed per-transaction fees (e.g., €0.20/txn). Fixed fees are acknowledged but not included in this analysis, as the synthetic dataset only provides rate-based fees. All fee calculations apply exclusively to successful transactions — Pending and Failed transactions carry €0 fees.
A29: Success Rate | B29: Defined as: COUNT(Status="Success") / COUNT(All Transactions). Pending transactions are NOT counted as failures.
A30: Net Amount EUR | B30: Gross Amount EUR − Fee Amount EUR. Only non-zero for successful transactions.
A31: Avg Transaction (All) | B31: AVERAGE across all 1,000 rows including €0 values for Pending/Failed. Denominator = total transactions.
A32: Avg Successful Txn | B32: AVERAGEIFS filtered to Status="Success" only. Denominator = successful transactions (554).
A33: GEO Ranking | B33: GEOs ranked by total transaction count. "Top 3" analysis covers NL (125), GB (113), CY (108).
A34: Decline Analysis | B34: Percentages calculated as share of failed transactions only (218 total), not share of all 1,000 transactions.
A35: SHEET INDEX
A36: # | B36: Sheet Name | C36: Purpose
A37: 1 | B37: Documentation | C37: This sheet — project overview, methodology, and assumptions
A38: 2 | B38: Raw Data (Jan-Jun) | C38: Original transaction records for January–June 2024 (485 rows)
A39: 3 | B39: Raw Data (Jul-Dec) | C39: Original transaction records for July–December 2024 (515 rows)
A40: 4 | B40: FX Rates | C40: Exchange rate reference table (SEK, NOK, EUR, GBP, PLN → EUR) with sources
A41: 5 | B41: Raw_Data_Combined | C41: Merged dataset with EUR-normalized columns (1,000 rows × 15 fields)
...

Sheet Raw Data (Jan-Jun)
A1: Transaction ID | B1: Date & Time | C1: GEO | D1: Currency | E1: PSP Provider | F1: Payment Method | G1: Amount | H1: Status | I1: Decline Reason | J1: Fee % | K1: Fee Amount | L1: Net Amount
A2: TXN00108 | B2: 45292.913 | C2: SE | D2: SEK | E2: Worldpay | F2: Bank Transfer | G2: 280.48 | H2: Pending | J2: 2.5 | K2: 0 | L2: 0
A3: TXN00929 | B3: 45294.356 | C3: NO | D3: NOK | E3: Worldpay | F3: E-Wallet | G3: 4887.84 | H3: Success | J3: 2.5 | K3: 122.2 | L3: 4765.64
A4: TXN00542 | B4: 45294.427 | C4: ES | D4: EUR | E4: Worldpay | F4: E-Wallet | G4: 4202.15 | H4: Success | J4: 2.5 | K4: 105.05 | L4: 4097.1
A5: TXN00520 | B5: 45294.437 | C5: FR | D5: EUR | E5: Stripe | F5: Debit Card | G5: 4643.85 | H5: Pending | J5: 2.9 | K5: 0 | L5: 0
A6: TXN00794 | B6: 45295.008 | C6: GB | D6: GBP | E6: Checkout.com | F6: E-Wallet | G6: 2086.95 | H6: Failed | I6: Card Declined | J6: 1.9 | K6: 0 | L6: 0
A7: TXN00712 | B7: 45295.155 | C7: PL | D7: PLN | E7: PaySafe | F7: Bank Transfer | G7: 3624.74 | H7: Pending | J7: 3.2 | K7: 0 | L7: 0
A8: TXN00652 | B8: 45295.385 | C8: ES | D8: EUR | E8: PaySafe | F8: Credit Card | G8: 3859.9 | H8: Success | J8: 3.2 | K8: 123.52 | L8: 3736.38
A9: TXN00600 | B9: 45296.226 | C9: NL | D9: EUR | E9: Adyen | F9: Crypto | G9: 2674.57 | H9: Success | J9: 2.1 | K9: 56.17 | L9: 2618.4
A10: TXN00388 | B10: 45296.467 | C10: IT | D10: EUR | E10: Checkout.com | F10: E-Wallet | G10: 3700.48 | H10: Success | J10: 1.9 | K10: 70.31 | L10: 3630.17
A11: TXN00617 | B11: 45296.577 | C11: IT | D11: EUR | E11: Checkout.com | F11: Debit Card | G11: 3985.87 | H11: Pending | J11: 1.9 | K11: 0 | L11: 0
A12: TXN00494 | B12: 45297.874 | C12: FR | D12: EUR | E12: Checkout.com | F12: Bank Transfer | G12: 4260.84 | H12: Success | J12: 1.9 | K12: 80.96 | L12: 4179.88
A13: TXN00643 | B13: 45298.278 | C13: NL | D13: EUR | E13: Stripe | F13: Bank Transfer | G13: 4007.09 | H13: Success | J13: 2.9 | K13: 116.21 | L13: 3890.88
A14: TXN00630 | B14: 45299.243 | C14: IT | D14: EUR | E14: Checkout.com | F14: Credit Card | G14: 1985.08 | H14: Success | J14: 1.9 | K14: 37.72 | L14: 1947.36
A15: TXN00292 | B15: 45299.291 | C15: ES | D15: EUR | E15: Stripe | F15: Bank Transfer | G15: 4573.06 | H15: Pending | J15: 2.9 | K15: 0 | L15: 0
A16: TXN00726 | B16: 45299.816 | C16: SE | D16: SEK | E16: Stripe | F16: Debit Card | G16: 2717.22 | H16: Pending | J16: 2.9 | K16: 0 | L16: 0
A17: TXN00265 | B17: 45299.973 | C17: IT | D17: EUR | E17: Checkout.com | F17: Debit Card | G17: 885.72 | H17: Failed | I17: Technical Error | J17: 1.9 | K17: 0 | L17: 0
A18: TXN00282 | B18: 45300.301 | C18: GB | D18: GBP | E18: Stripe | F18: Crypto | G18: 177.55 | H18: Pending | J18: 2.9 | K18: 0 | L18: 0
A19: TXN00860 | B19: 45301.658 | C19: CY | D19: EUR | E19: Stripe | F19: Debit Card | G19: 548.01 | H19: Pending | J19: 2.9 | K19: 0 | L19: 0
A20: TXN00545 | B20: 45301.694 | C20: DE | D20: EUR | E20: Checkout.com | F20: Crypto | G20: 2031.62 | H20: Pending | J20: 1.9 | K20: 0 | L20: 0
A21: TXN00896 | B21: 45301.865 | C21: SE | D21: SEK | E21: Adyen | F21: Crypto | G21: 2501.03 | H21: Failed | I21: Fraud Suspected | J21: 2.1 | K21: 0 | L21: 0
A22: TXN00920 | B22: 45302.041 | C22: SE | D22: SEK | E22: Checkout.com | F22: Debit Card | G22: 4535.16 | H22: Failed | I22: Card Declined | J22: 1.9 | K22: 0 | L22: 0
A23: TXN00426 | B23: 45302.428 | C23: GB | D23: GBP | E23: Stripe | F23: E-Wallet | G23: 858.82 | H23: Failed | I23: Card Declined | J23: 2.9 | K23: 0 | L23: 0
A24: TXN00634 | B24: 45302.933 | C24: PL | D24: PLN | E24: Adyen | F24: E-Wallet | G24: 4494.33 | H24: Failed | I24: Technical Error | J24: 2.1 | K24: 0 | L24: 0
A25: TXN00280 | B25: 45303.395 | C25: SE | D25: SEK | E25: Worldpay | F25: Crypto | G25: 1902.59 | H25: Success | J25: 2.5 | K25: 47.56 | L25: 1855.03
A26: TXN00724 | B26: 45303.783 | C26: IT | D26: EUR | E26: Adyen | F26: E-Wallet | G26: 1010.77 | H26: Success | J26: 2.1 | K26: 21.23 | L26: 989.54
A27: TXN00047 | B27: 45304.241 | C27: PL | D27: PLN | E27: Worldpay | F27: Debit Card | G27: 1341.36 | H27: Success | J27: 2.5 | K27: 33.53 | L27: 1307.83
A28: TXN00526 | B28: 45304.703 | C28: PL | D28: PLN | E28: Checkout.com | F28: Crypto | G28: 2233.33 | H28: Success | J28: 1.9 | K28: 42.43 | L28: 2190.9
A29: TXN00049 | B29: 45304.883 | C29: CY | D29: EUR | E29: PaySafe | F29: E-Wallet | G29: 4323.12 | H29: Success | J29: 3.2 | K29: 138.34 | L29: 4184.78
A30: TXN00848 | B30: 45306.158 | C30: IT | D30: EUR | E30: Worldpay | F30: Credit Card | G30: 2998.47 | H30: Success | J30: 2.5 | K30: 74.96 | L30: 2923.51
A31: TXN00404 | B31: 45307.53 | C31: CY | D31: EUR | E31: Adyen | F31: E-Wallet | G31: 1081.43 | H31: Success | J31: 2.1 | K31: 22.71 | L31: 1058.72
A32: TXN00980 | B32: 45307.59 | C32: DE | D32: EUR | E32: Checkout.com | F32: Credit Card | G32: 433.04 | H32: Success | J32: 1.9 | K32: 8.23 | L32: 424.81
A33: TXN00641 | B33: 45308.254 | C33: NL | D33: EUR | E33: Adyen | F33: Credit Card | G33: 168.77 | H33: Failed | I33: Technical Error | J33: 2.1 | K33: 0 | L33: 0
A34: TXN00011 | B34: 45308.434 | C34: IT | D34: EUR | E34: Stripe | F34: Debit Card | G34: 4566.55 | H34: Pending | J34: 2.9 | K34: 0 | L34: 0
A35: TXN00879 | B35: 45308.581 | C35: GB | D35: GBP | E35: Worldpay | F35: Bank Transfer | G35: 1579.65 | H35: Failed | I35: Technical Error | J35: 2.5 | K35: 0 | L35: 0
A36: TXN00996 | B36: 45308.965 | C36: SE | D36: SEK | E36: PaySafe | F36: Credit Card | G36: 3011.99 | H36: Failed | I36: Insufficient Funds | J36: 3.2 | K36: 0 | L36: 0
A37: TXN00215 | B37: 45309.169 | C37: ES | D37: EUR | E37: PaySafe | F37: E-Wallet | G37: 1920.44 | H37: Pending | J37: 3.2 | K37: 0 | L37: 0
A38: TXN00627 | B38: 45309.27 | C38: GB | D38: GBP | E38: Checkout.com | F38: Debit Card | G38: 2369.4 | H38: Success | J38: 1.9 | K38: 45.02 | L38: 2324.38
A39: TXN00612 | B39: 45309.89 | C39: PL | D39: PLN | E39: Worldpay | F39: Bank Transfer | G39: 4875.16 | H39: Pending | J39: 2.5 | K39: 0 | L39: 0
A40: TXN00118 | B40: 45310.189 | C40: NO | D40: NOK | E40: PaySafe | F40: Credit Card | G40: 4372.21 | H40: Failed | I40: Insufficient Funds | J40: 3.2 | K40: 0 | L40: 0
...

Sheet Raw Data (Jul-Dec)
A1: Transaction ID | B1: Date & Time | C1: GEO | D1: Currency | E1: PSP Provider | F1: Payment Method | G1: Amount | H1: Status | I1: Decline Reason | J1: Fee % | K1: Fee Amount | L1: Net Amount
A2: TXN00837 | B2: 45474.097 | C2: DE | D2: EUR | E2: Checkout.com | F2: Debit Card | G2: 2921.32 | H2: Success | J2: 1.9 | K2: 55.51 | L2: 2865.81
A3: TXN00971 | B3: 45474.882 | C3: FR | D3: EUR | E3: Checkout.com | F3: Credit Card | G3: 4036.01 | H3: Success | J3: 1.9 | K3: 76.68 | L3: 3959.33
A4: TXN00486 | B4: 45475.61 | C4: IT | D4: EUR | E4: Stripe | F4: E-Wallet | G4: 4076.67 | H4: Success | J4: 2.9 | K4: 118.22 | L4: 3958.45
A5: TXN00945 | B5: 45475.879 | C5: PL | D5: PLN | E5: Checkout.com | F5: Debit Card | G5: 2453.22 | H5: Failed | I5: Technical Error | J5: 1.9 | K5: 0 | L5: 0
A6: TXN00481 | B6: 45475.935 | C6: IT | D6: EUR | E6: Adyen | F6: Credit Card | G6: 2745.21 | H6: Success | J6: 2.1 | K6: 57.65 | L6: 2687.56
A7: TXN00747 | B7: 45476.548 | C7: IT | D7: EUR | E7: Adyen | F7: Debit Card | G7: 67.9 | H7: Success | J7: 2.1 | K7: 1.43 | L7: 66.47
A8: TXN00149 | B8: 45477.692 | C8: GB | D8: GBP | E8: Worldpay | F8: Crypto | G8: 1115.53 | H8: Pending | J8: 2.5 | K8: 0 | L8: 0
A9: TXN00556 | B9: 45477.823 | C9: GB | D9: GBP | E9: Adyen | F9: Bank Transfer | G9: 4057.75 | H9: Success | J9: 2.1 | K9: 85.21 | L9: 3972.54
A10: TXN00499 | B10: 45478.078 | C10: ES | D10: EUR | E10: Worldpay | F10: E-Wallet | G10: 2805.15 | H10: Pending | J10: 2.5 | K10: 0 | L10: 0
A11: TXN00326 | B11: 45478.166 | C11: NO | D11: NOK | E11: Adyen | F11: Crypto | G11: 4986.35 | H11: Success | J11: 2.1 | K11: 104.71 | L11: 4881.64
A12: TXN00898 | B12: 45478.59 | C12: ES | D12: EUR | E12: Adyen | F12: E-Wallet | G12: 4222.17 | H12: Failed | I12: Fraud Suspected | J12: 2.1 | K12: 0 | L12: 0
A13: TXN00240 | B13: 45479.059 | C13: DE | D13: EUR | E13: Checkout.com | F13: Crypto | G13: 981.33 | H13: Pending | J13: 1.9 | K13: 0 | L13: 0
A14: TXN00135 | B14: 45479.118 | C14: CY | D14: EUR | E14: Stripe | F14: E-Wallet | G14: 2687.5 | H14: Failed | I14: Fraud Suspected | J14: 2.9 | K14: 0 | L14: 0
A15: TXN00597 | B15: 45479.23 | C15: CY | D15: EUR | E15: Adyen | F15: Bank Transfer | G15: 3506.56 | H15: Success | J15: 2.1 | K15: 73.64 | L15: 3432.92
A16: TXN00664 | B16: 45479.467 | C16: PL | D16: PLN | E16: PaySafe | F16: Crypto | G16: 3280.5 | H16: Success | J16: 3.2 | K16: 104.98 | L16: 3175.52
A17: TXN00374 | B17: 45479.738 | C17: FR | D17: EUR | E17: Worldpay | F17: Credit Card | G17: 93.28 | H17: Success | J17: 2.5 | K17: 2.33 | L17: 90.95
A18: TXN00389 | B18: 45480.772 | C18: ES | D18: EUR | E18: Checkout.com | F18: Debit Card | G18: 761.33 | H18: Failed | I18: Insufficient Funds | J18: 1.9 | K18: 0 | L18: 0
A19: TXN00192 | B19: 45480.9 | C19: NL | D19: EUR | E19: Worldpay | F19: E-Wallet | G19: 3892.84 | H19: Pending | J19: 2.5 | K19: 0 | L19: 0
A20: TXN00290 | B20: 45481.107 | C20: ES | D20: EUR | E20: Stripe | F20: E-Wallet | G20: 1892.07 | H20: Pending | J20: 2.9 | K20: 0 | L20: 0
A21: TXN00572 | B21: 45481.733 | C21: NL | D21: EUR | E21: PaySafe | F21: E-Wallet | G21: 2892.48 | H21: Failed | I21: Card Declined | J21: 3.2 | K21: 0 | L21: 0
A22: TXN00182 | B22: 45482.392 | C22: CY | D22: EUR | E22: PaySafe | F22: Crypto | G22: 271.3 | H22: Success | J22: 3.2 | K22: 8.68 | L22: 262.62
A23: TXN00829 | B23: 45482.409 | C23: DE | D23: EUR | E23: Adyen | F23: E-Wallet | G23: 1429.07 | H23: Success | J23: 2.1 | K23: 30.01 | L23: 1399.06
A24: TXN00998 | B24: 45483.387 | C24: NL | D24: EUR | E24: Stripe | F24: Debit Card | G24: 719.28 | H24: Pending | J24: 2.9 | K24: 0 | L24: 0
A25: TXN00305 | B25: 45483.52 | C25: NO | D25: NOK | E25: Adyen | F25: Debit Card | G25: 1506.87 | H25: Success | J25: 2.1 | K25: 31.64 | L25: 1475.23
A26: TXN00939 | B26: 45483.791 | C26: GB | D26: GBP | E26: PaySafe | F26: Debit Card | G26: 154.08 | H26: Failed | I26: Technical Error | J26: 3.2 | K26: 0 | L26: 0
A27: TXN00252 | B27: 45484.424 | C27: NL | D27: EUR | E27: Checkout.com | F27: E-Wallet | G27: 2735.9 | H27: Success | J27: 1.9 | K27: 51.98 | L27: 2683.92
A28: TXN00553 | B28: 45484.85 | C28: PL | D28: PLN | E28: Checkout.com | F28: Credit Card | G28: 2588.15 | H28: Failed | I28: Card Declined | J28: 1.9 | K28: 0 | L28: 0
A29: TXN00519 | B29: 45485.06 | C29: IT | D29: EUR | E29: Checkout.com | F29: E-Wallet | G29: 659.03 | H29: Pending | J29: 1.9 | K29: 0 | L29: 0
A30: TXN00419 | B30: 45485.407 | C30: IT | D30: EUR | E30: Adyen | F30: Debit Card | G30: 3646.87 | H30: Pending | J30: 2.1 | K30: 0 | L30: 0
A31: TXN00704 | B31: 45486.117 | C31: CY | D31: EUR | E31: Checkout.com | F31: Credit Card | G31: 1471.24 | H31: Success | J31: 1.9 | K31: 27.95 | L31: 1443.29
A32: TXN00672 | B32: 45486.698 | C32: GB | D32: GBP | E32: PaySafe | F32: Bank Transfer | G32: 4335.2 | H32: Pending | J32: 3.2 | K32: 0 | L32: 0
A33: TXN00765 | B33: 45486.906 | C33: CY | D33: EUR | E33: Worldpay | F33: E-Wallet | G33: 734.3 | H33: Failed | I33: Insufficient Funds | J33: 2.5 | K33: 0 | L33: 0
A34: TXN00775 | B34: 45487.515 | C34: DE | D34: EUR | E34: PaySafe | F34: E-Wallet | G34: 897.87 | H34: Success | J34: 3.2 | K34: 28.73 | L34: 869.14
A35: TXN00746 | B35: 45487.565 | C35: ES | D35: EUR | E35: Adyen | F35: Bank Transfer | G35: 703.95 | H35: Pending | J35: 2.1 | K35: 0 | L35: 0
A36: TXN00278 | B36: 45487.622 | C36: CY | D36: EUR | E36: Worldpay | F36: Credit Card | G36: 3416.82 | H36: Pending | J36: 2.5 | K36: 0 | L36: 0
A37: TXN00729 | B37: 45488.045 | C37: CY | D37: EUR | E37: Worldpay | F37: Debit Card | G37: 3526.34 | H37: Pending | J37: 2.5 | K37: 0 | L37: 0
A38: TXN00563 | B38: 45489.171 | C38: DE | D38: EUR | E38: Adyen | F38: Crypto | G38: 4299.36 | H38: Pending | J38: 2.1 | K38: 0 | L38: 0
A39: TXN00869 | B39: 45489.395 | C39: NO | D39: NOK | E39: PaySafe | F39: Bank Transfer | G39: 1137.11 | H39: Failed | I39: Fraud Suspected | J39: 3.2 | K39: 0 | L39: 0
A40: TXN00805 | B40: 45490.464 | C40: NL | D40: EUR | E40: Adyen | F40: E-Wallet | G40: 4878.02 | H40: Success | J40: 2.1 | K40: 102.44 | L40: 4775.58
...

Sheet FX Rates
A1: FX Rates (to EUR) - 2024 Annual Average
A2: Currency | B2: Rate to EUR | C2: Source
A3: SEK | B3: 0.0874 | C3: ECB (2024 Avg)
A4: NOK | B4: 0.086 | C4: ECB (2024 Avg)
A5: EUR | B5: 1 | C5: ECB (2024 Avg)
A6: GBP | B6: 1.1802 | C6: ECB (2024 Avg)
A7: PLN | B7: 0.2327 | C7: ECB (2024 Avg)

Sheet Raw_Data_Combined
A1: Transaction ID | B1: Date & Time | C1: GEO | D1: Currency | E1: PSP Provider | F1: Payment Method | G1: Amount | H1: Status | I1: Decline Reason | J1: Fee % | K1: Exchange Rate to EUR | L1: Fee Amount EUR | M1: Net Amount EUR | N1: Gross Amount EUR | O1: Month Name
A2: TXN00108 | B2: 45292.913 | C2: SE | D2: SEK | E2: Worldpay | F2: Bank Transfer | G2: 280.48 | H2: Pending | J2: 2.5 | K2: 0.0874 | L2: 0 | M2: 0 | N2: 0 | O2: January
A3: TXN00929 | B3: 45294.356 | C3: NO | D3: NOK | E3: Worldpay | F3: E-Wallet | G3: 4887.84 | H3: Success | J3: 2.5 | K3: 0.086 | L3: 10.5092 | M3: 409.84504 | N3: 420.35424 | O3: January
A4: TXN00542 | B4: 45294.427 | C4: ES | D4: EUR | E4: Worldpay | F4: E-Wallet | G4: 4202.15 | H4: Success | J4: 2.5 | K4: 1 | L4: 105.05 | M4: 4097.1 | N4: 4202.15 | O4: January
A5: TXN00520 | B5: 45294.437 | C5: FR | D5: EUR | E5: Stripe | F5: Debit Card | G5: 4643.85 | H5: Pending | J5: 2.9 | K5: 1 | L5: 0 | M5: 0 | N5: 0 | O5: January
A6: TXN00794 | B6: 45295.008 | C6: GB | D6: GBP | E6: Checkout.com | F6: E-Wallet | G6: 2086.95 | H6: Failed | I6: Card Declined | J6: 1.9 | K6: 1.1802 | L6: 0 | M6: 0 | N6: 0 | O6: January
A7: TXN00712 | B7: 45295.155 | C7: PL | D7: PLN | E7: PaySafe | F7: Bank Transfer | G7: 3624.74 | H7: Pending | J7: 3.2 | K7: 0.2327 | L7: 0 | M7: 0 | N7: 0 | O7: January
A8: TXN00652 | B8: 45295.385 | C8: ES | D8: EUR | E8: PaySafe | F8: Credit Card | G8: 3859.9 | H8: Success | J8: 3.2 | K8: 1 | L8: 123.52 | M8: 3736.38 | N8: 3859.9 | O8: January
A9: TXN00600 | B9: 45296.226 | C9: NL | D9: EUR | E9: Adyen | F9: Crypto | G9: 2674.57 | H9: Success | J9: 2.1 | K9: 1 | L9: 56.17 | M9: 2618.4 | N9: 2674.57 | O9: January
A10: TXN00388 | B10: 45296.467 | C10: IT | D10: EUR | E10: Checkout.com | F10: E-Wallet | G10: 3700.48 | H10: Success | J10: 1.9 | K10: 1 | L10: 70.31 | M10: 3630.17 | N10: 3700.48 | O10: January
A11: TXN00617 | B11: 45296.577 | C11: IT | D11: EUR | E11: Checkout.com | F11: Debit Card | G11: 3985.87 | H11: Pending | J11: 1.9 | K11: 1 | L11: 0 | M11: 0 | N11: 0 | O11: January
A12: TXN00494 | B12: 45297.874 | C12: FR | D12: EUR | E12: Checkout.com | F12: Bank Transfer | G12: 4260.84 | H12: Success | J12: 1.9 | K12: 1 | L12: 80.96 | M12: 4179.88 | N12: 4260.84 | O12: January
A13: TXN00643 | B13: 45298.278 | C13: NL | D13: EUR | E13: Stripe | F13: Bank Transfer | G13: 4007.09 | H13: Success | J13: 2.9 | K13: 1 | L13: 116.21 | M13: 3890.88 | N13: 4007.09 | O13: January
A14: TXN00630 | B14: 45299.243 | C14: IT | D14: EUR | E14: Checkout.com | F14: Credit Card | G14: 1985.08 | H14: Success | J14: 1.9 | K14: 1 | L14: 37.72 | M14: 1947.36 | N14: 1985.08 | O14: January
A15: TXN00292 | B15: 45299.291 | C15: ES | D15: EUR | E15: Stripe | F15: Bank Transfer | G15: 4573.06 | H15: Pending | J15: 2.9 | K15: 1 | L15: 0 | M15: 0 | N15: 0 | O15: January
A16: TXN00726 | B16: 45299.816 | C16: SE | D16: SEK | E16: Stripe | F16: Debit Card | G16: 2717.22 | H16: Pending | J16: 2.9 | K16: 0.0874 | L16: 0 | M16: 0 | N16: 0 | O16: January
A17: TXN00265 | B17: 45299.973 | C17: IT | D17: EUR | E17: Checkout.com | F17: Debit Card | G17: 885.72 | H17: Failed | I17: Technical Error | J17: 1.9 | K17: 1 | L17: 0 | M17: 0 | N17: 0 | O17: January
A18: TXN00282 | B18: 45300.301 | C18: GB | D18: GBP | E18: Stripe | F18: Crypto | G18: 177.55 | H18: Pending | J18: 2.9 | K18: 1.1802 | L18: 0 | M18: 0 | N18: 0 | O18: January
A19: TXN00860 | B19: 45301.658 | C19: CY | D19: EUR | E19: Stripe | F19: Debit Card | G19: 548.01 | H19: Pending | J19: 2.9 | K19: 1 | L19: 0 | M19: 0 | N19: 0 | O19: January
A20: TXN00545 | B20: 45301.694 | C20: DE | D20: EUR | E20: Checkout.com | F20: Crypto | G20: 2031.62 | H20: Pending | J20: 1.9 | K20: 1 | L20: 0 | M20: 0 | N20: 0 | O20: January
A21: TXN00896 | B21: 45301.865 | C21: SE | D21: SEK | E21: Adyen | F21: Crypto | G21: 2501.03 | H21: Failed | I21: Fraud Suspected | J21: 2.1 | K21: 0.0874 | L21: 0 | M21: 0 | N21: 0 | O21: January
A22: TXN00920 | B22: 45302.041 | C22: SE | D22: SEK | E22: Checkout.com | F22: Debit Card | G22: 4535.16 | H22: Failed | I22: Card Declined | J22: 1.9 | K22: 0.0874 | L22: 0 | M22: 0 | N22: 0 | O22: January
A23: TXN00426 | B23: 45302.428 | C23: GB | D23: GBP | E23: Stripe | F23: E-Wallet | G23: 858.82 | H23: Failed | I23: Card Declined | J23: 2.9 | K23: 1.1802 | L23: 0 | M23: 0 | N23: 0 | O23: January
A24: TXN00634 | B24: 45302.933 | C24: PL | D24: PLN | E24: Adyen | F24: E-Wallet | G24: 4494.33 | H24: Failed | I24: Technical Error | J24: 2.1 | K24: 0.2327 | L24: 0 | M24: 0 | N24: 0 | O24: January
A25: TXN00280 | B25: 45303.395 | C25: SE | D25: SEK | E25: Worldpay | F25: Crypto | G25: 1902.59 | H25: Success | J25: 2.5 | K25: 0.0874 | L25: 4.156744 | M25: 162.12962 | N25: 166.28637 | O25: January
A26: TXN00724 | B26: 45303.783 | C26: IT | D26: EUR | E26: Adyen | F26: E-Wallet | G26: 1010.77 | H26: Success | J26: 2.1 | K26: 1 | L26: 21.23 | M26: 989.54 | N26: 1010.77 | O26: January
A27: TXN00047 | B27: 45304.241 | C27: PL | D27: PLN | E27: Worldpay | F27: Debit Card | G27: 1341.36 | H27: Success | J27: 2.5 | K27: 0.2327 | L27: 7.802431 | M27: 304.33204 | N27: 312.13447 | O27: January
A28: TXN00526 | B28: 45304.703 | C28: PL | D28: PLN | E28: Checkout.com | F28: Crypto | G28: 2233.33 | H28: Success | J28: 1.9 | K28: 0.2327 | L28: 9.873461 | M28: 509.82243 | N28: 519.69589 | O28: January
A29: TXN00049 | B29: 45304.883 | C29: CY | D29: EUR | E29: PaySafe | F29: E-Wallet | G29: 4323.12 | H29: Success | J29: 3.2 | K29: 1 | L29: 138.34 | M29: 4184.78 | N29: 4323.12 | O29: January
A30: TXN00848 | B30: 45306.158 | C30: IT | D30: EUR | E30: Worldpay | F30: Credit Card | G30: 2998.47 | H30: Success | J30: 2.5 | K30: 1 | L30: 74.96 | M30: 2923.51 | N30: 2998.47 | O30: January
A31: TXN00404 | B31: 45307.53 | C31: CY | D31: EUR | E31: Adyen | F31: E-Wallet | G31: 1081.43 | H31: Success | J31: 2.1 | K31: 1 | L31: 22.71 | M31: 1058.72 | N31: 1081.43 | O31: January
A32: TXN00980 | B32: 45307.59 | C32: DE | D32: EUR | E32: Checkout.com | F32: Credit Card | G32: 433.04 | H32: Success | J32: 1.9 | K32: 1 | L32: 8.23 | M32: 424.81 | N32: 433.04 | O32: January
A33: TXN00641 | B33: 45308.254 | C33: NL | D33: EUR | E33: Adyen | F33: Credit Card | G33: 168.77 | H33: Failed | I33: Technical Error | J33: 2.1 | K33: 1 | L33: 0 | M33: 0 | N33: 0 | O33: January
A34: TXN00011 | B34: 45308.434 | C34: IT | D34: EUR | E34: Stripe | F34: Debit Card | G34: 4566.55 | H34: Pending | J34: 2.9 | K34: 1 | L34: 0 | M34: 0 | N34: 0 | O34: January
A35: TXN00879 | B35: 45308.581 | C35: GB | D35: GBP | E35: Worldpay | F35: Bank Transfer | G35: 1579.65 | H35: Failed | I35: Technical Error | J35: 2.5 | K35: 1.1802 | L35: 0 | M35: 0 | N35: 0 | O35: January
A36: TXN00996 | B36: 45308.965 | C36: SE | D36: SEK | E36: PaySafe | F36: Credit Card | G36: 3011.99 | H36: Failed | I36: Insufficient Funds | J36: 3.2 | K36: 0.0874 | L36: 0 | M36: 0 | N36: 0 | O36: January
A37: TXN00215 | B37: 45309.169 | C37: ES | D37: EUR | E37: PaySafe | F37: E-Wallet | G37: 1920.44 | H37: Pending | J37: 3.2 | K37: 1 | L37: 0 | M37: 0 | N37: 0 | O37: January
A38: TXN00627 | B38: 45309.27 | C38: GB | D38: GBP | E38: Checkout.com | F38: Debit Card | G38: 2369.4 | H38: Success | J38: 1.9 | K38: 1.1802 | L38: 53.132604 | M38: 2743.2333 | N38: 2796.3659 | O38: January
A39: TXN00612 | B39: 45309.89 | C39: PL | D39: PLN | E39: Worldpay | F39: Bank Transfer | G39: 4875.16 | H39: Pending | J39: 2.5 | K39: 0.2327 | L39: 0 | M39: 0 | N39: 0 | O39: January
A40: TXN00118 | B40: 45310.189 | C40: NO | D40: NOK | E40: PaySafe | F40: Credit Card | G40: 4372.21 | H40: Failed | I40: Insufficient Funds | J40: 3.2 | K40: 0.086 | L40: 0 | M40: 0 | N40: 0 | O40: January
...

Sheet Tasks
B2: Task 1 — Conversion Rate by PSP Provider
B4: n/n | C4: PSP Provider | D4: Success Transactions | E4: Overall Transactions | F4: Success Rate (%)
B5: 1 | C5: {=_xlfn.UNIQUE('Raw_Data_Combined'!$E$2:$E$1001)} -> Worldpay | D5: =COUNTIFS(Raw_Data_Combined[PSP Provider],$C5,Raw_Data_Combined[Status],"Success") -> 105 | E5: =COUNTIF(Raw_Data_Combined[PSP Provider],Tasks!$C5) -> 194 | F5: =D5/E5 -> 0.54123711
B6: 2 | C6: Stripe | D6: =COUNTIFS(Raw_Data_Combined[PSP Provider],$C6,Raw_Data_Combined[Status],"Success") -> 101 | E6: =COUNTIF(Raw_Data_Combined[PSP Provider],Tasks!$C6) -> 186 | F6: =D6/E6 -> 0.54301075
B7: 3 | C7: Checkout.com | D7: =COUNTIFS(Raw_Data_Combined[PSP Provider],$C7,Raw_Data_Combined[Status],"Success") -> 130 | E7: =COUNTIF(Raw_Data_Combined[PSP Provider],Tasks!$C7) -> 221 | F7: =D7/E7 -> 0.58823529
B8: 4 | C8: PaySafe | D8: =COUNTIFS(Raw_Data_Combined[PSP Provider],$C8,Raw_Data_Combined[Status],"Success") -> 120 | E8: =COUNTIF(Raw_Data_Combined[PSP Provider],Tasks!$C8) -> 210 | F8: =D8/E8 -> 0.57142857
B9: 5 | C9: Adyen | D9: =COUNTIFS(Raw_Data_Combined[PSP Provider],$C9,Raw_Data_Combined[Status],"Success") -> 98 | E9: =COUNTIF(Raw_Data_Combined[PSP Provider],Tasks!$C9) -> 189 | F9: =D9/E9 -> 0.51851852
B13: Task 2 — Revenue & Fee Analysis by Provider
B15: n/n | C15: PSP Provider | D15: Net Amount (€) | E15: Fee Amount (€) | F15: Overall Transactions
B16: 1 | C16: {=_xlfn.UNIQUE('Raw_Data_Combined'!$E$2:$E$1001)} -> Worldpay | D16: =SUMIFS(Raw_Data_Combined[Net Amount EUR],Raw_Data_Combined[PSP Provider],$C16) -> 173586.54 | E16: =SUMIFS(Raw_Data_Combined[Fee Amount EUR],Raw_Data_Combined[PSP Provider],$C16) -> 4450.9076 | F16: =_xlfn.XLOOKUP($C16,$C$5:$C$9,$E$5:$E$9) -> 194
B17: 2 | C17: Stripe | D17: =SUMIFS(Raw_Data_Combined[Net Amount EUR],Raw_Data_Combined[PSP Provider],$C17) -> 192606.49 | E17: =SUMIFS(Raw_Data_Combined[Fee Amount EUR],Raw_Data_Combined[PSP Provider],$C17) -> 5752.3726 | F17: =_xlfn.XLOOKUP($C17,$C$5:$C$9,$E$5:$E$9) -> 186
B18: 3 | C18: Checkout.com | D18: =SUMIFS(Raw_Data_Combined[Net Amount EUR],Raw_Data_Combined[PSP Provider],$C18) -> 249324.19 | E18: =SUMIFS(Raw_Data_Combined[Fee Amount EUR],Raw_Data_Combined[PSP Provider],$C18) -> 4828.8748 | F18: =_xlfn.XLOOKUP($C18,$C$5:$C$9,$E$5:$E$9) -> 221
B19: 4 | C19: PaySafe | D19: =SUMIFS(Raw_Data_Combined[Net Amount EUR],Raw_Data_Combined[PSP Provider],$C19) -> 215751.9 | E19: =SUMIFS(Raw_Data_Combined[Fee Amount EUR],Raw_Data_Combined[PSP Provider],$C19) -> 7132.3015 | F19: =_xlfn.XLOOKUP($C19,$C$5:$C$9,$E$5:$E$9) -> 210
B20: 5 | C20: Adyen | D20: =SUMIFS(Raw_Data_Combined[Net Amount EUR],Raw_Data_Combined[PSP Provider],$C20) -> 193122.18 | E20: =SUMIFS(Raw_Data_Combined[Fee Amount EUR],Raw_Data_Combined[PSP Provider],$C20) -> 4142.5884 | F20: =_xlfn.XLOOKUP($C20,$C$5:$C$9,$E$5:$E$9) -> 189
B24: Task 3 — Performance by GEO
B26: n/n | C26: GEO | D26: Overall Transactions | E26: Success Rate (%) | F26: Avg Transaction Amount (All Statuses, €) | G26: Success Average Transaction Amount (€) | H26: Net Revenue (€)
B27: 1 | C27: {=_xlfn.UNIQUE('Raw_Data_Combined'!$C$2:$C$1001)} -> SE | D27: =COUNTIF(Raw_Data_Combined[GEO],$C27) -> 100 | E27: =COUNTIFS(Raw_Data_Combined[GEO],$C27,Raw_Data_Combined[Status],"Success")/$D27 -> 0.49 | F27: =AVERAGEIF(Raw_Data_Combined[GEO],Tasks!C27,Raw_Data_Combined[Gross Amount EUR]) -> 94.825766 | G27: =AVERAGEIFS(Raw_Data_Combined[Gross Amount EUR],Raw_Data_Combined[GEO],Tasks!$C27,Raw_Data_Combined[Status],"Success") -> 193.52197 | H27: =SUMIFS(Raw_Data_Combined[Net Amount EUR],Raw_Data_Combined[GEO],$C27) -> 9240.6298
B28: 2 | C28: NO | D28: =COUNTIF(Raw_Data_Combined[GEO],$C28) -> 98 | E28: =COUNTIFS(Raw_Data_Combined[GEO],$C28,Raw_Data_Combined[Status],"Success")/$D28 -> 0.58163265 | F28: =AVERAGEIF(Raw_Data_Combined[GEO],Tasks!C28,Raw_Data_Combined[Gross Amount EUR]) -> 116.35897 | G28: =AVERAGEIFS(Raw_Data_Combined[Gross Amount EUR],Raw_Data_Combined[GEO],Tasks!$C28,Raw_Data_Combined[Status],"Success") -> 200.05576 | H28: =SUMIFS(Raw_Data_Combined[Net Amount EUR],Raw_Data_Combined[GEO],$C28) -> 11128.355
B29: 3 | C29: ES | D29: =COUNTIF(Raw_Data_Combined[GEO],$C29) -> 80 | E29: =COUNTIFS(Raw_Data_Combined[GEO],$C29,Raw_Data_Combined[Status],"Success")/$D29 -> 0.5125 | F29: =AVERAGEIF(Raw_Data_Combined[GEO],Tasks!C29,Raw_Data_Combined[Gross Amount EUR]) -> 1418.3263 | G29: =AVERAGEIFS(Raw_Data_Combined[Gross Amount EUR],Raw_Data_Combined[GEO],Tasks!$C29,Raw_Data_Combined[Status],"Success") -> 2767.4659 | H29: =SUMIFS(Raw_Data_Combined[Net Amount EUR],Raw_Data_Combined[GEO],$C29) -> 110471.49
B30: 4 | C30: FR | D30: =COUNTIF(Raw_Data_Combined[GEO],$C30) -> 101 | E30: =COUNTIFS(Raw_Data_Combined[GEO],$C30,Raw_Data_Combined[Status],"Success")/$D30 -> 0.63366337 | F30: =AVERAGEIF(Raw_Data_Combined[GEO],Tasks!C30,Raw_Data_Combined[Gross Amount EUR]) -> 1773.3712 | G30: =AVERAGEIFS(Raw_Data_Combined[Gross Amount EUR],Raw_Data_Combined[GEO],Tasks!$C30,Raw_Data_Combined[Status],"Success") -> 2798.6014 | H30: =SUMIFS(Raw_Data_Combined[Net Amount EUR],Raw_Data_Combined[GEO],$C30) -> 174641.67
B31: 5 | C31: GB | D31: =COUNTIF(Raw_Data_Combined[GEO],$C31) -> 113 | E31: =COUNTIFS(Raw_Data_Combined[GEO],$C31,Raw_Data_Combined[Status],"Success")/$D31 -> 0.51327434 | F31: =AVERAGEIF(Raw_Data_Combined[GEO],Tasks!C31,Raw_Data_Combined[Gross Amount EUR]) -> 1467.2815 | G31: =AVERAGEIFS(Raw_Data_Combined[Gross Amount EUR],Raw_Data_Combined[GEO],Tasks!$C31,Raw_Data_Combined[Status],"Success") -> 2858.669 | H31: =SUMIFS(Raw_Data_Combined[Net Amount EUR],Raw_Data_Combined[GEO],$C31) -> 161735.55
B32: 6 | C32: PL | D32: =COUNTIF(Raw_Data_Combined[GEO],$C32) -> 97 | E32: =COUNTIFS(Raw_Data_Combined[GEO],$C32,Raw_Data_Combined[Status],"Success")/$D32 -> 0.57731959 | F32: =AVERAGEIF(Raw_Data_Combined[GEO],Tasks!C32,Raw_Data_Combined[Gross Amount EUR]) -> 373.92335 | G32: =AVERAGEIFS(Raw_Data_Combined[Gross Amount EUR],Raw_Data_Combined[GEO],Tasks!$C32,Raw_Data_Combined[Status],"Success") -> 647.68866 | H32: =SUMIFS(Raw_Data_Combined[Net Amount EUR],Raw_Data_Combined[GEO],$C32) -> 35308.793
B33: 7 | C33: NL | D33: =COUNTIF(Raw_Data_Combined[GEO],$C33) -> 125 | E33: =COUNTIFS(Raw_Data_Combined[GEO],$C33,Raw_Data_Combined[Status],"Success")/$D33 -> 0.56 | F33: =AVERAGEIF(Raw_Data_Combined[GEO],Tasks!C33,Raw_Data_Combined[Gross Amount EUR]) -> 1287.8441 | G33: =AVERAGEIFS(Raw_Data_Combined[Gross Amount EUR],Raw_Data_Combined[GEO],Tasks!$C33,Raw_Data_Combined[Status],"Success") -> 2299.7216 | H33: =SUMIFS(Raw_Data_Combined[Net Amount EUR],Raw_Data_Combined[GEO],$C33) -> 157032.23
B34: 8 | C34: IT | D34: =COUNTIF(Raw_Data_Combined[GEO],$C34) -> 91 | E34: =COUNTIFS(Raw_Data_Combined[GEO],$C34,Raw_Data_Combined[Status],"Success")/$D34 -> 0.6043956 | F34: =AVERAGEIF(Raw_Data_Combined[GEO],Tasks!C34,Raw_Data_Combined[Gross Amount EUR]) -> 1358.9085 | G34: =AVERAGEIFS(Raw_Data_Combined[Gross Amount EUR],Raw_Data_Combined[GEO],Tasks!$C34,Raw_Data_Combined[Status],"Success") -> 2248.3758 | H34: =SUMIFS(Raw_Data_Combined[Net Amount EUR],Raw_Data_Combined[GEO],$C34) -> 120668.87
B35: 9 | C35: CY | D35: =COUNTIF(Raw_Data_Combined[GEO],$C35) -> 108 | E35: =COUNTIFS(Raw_Data_Combined[GEO],$C35,Raw_Data_Combined[Status],"Success")/$D35 -> 0.56481481 | F35: =AVERAGEIF(Raw_Data_Combined[GEO],Tasks!C35,Raw_Data_Combined[Gross Amount EUR]) -> 1416.9217 | G35: =AVERAGEIFS(Raw_Data_Combined[Gross Amount EUR],Raw_Data_Combined[GEO],Tasks!$C35,Raw_Data_Combined[Status],"Success") -> 2508.6482 | H35: =SUMIFS(Raw_Data_Combined[Net Amount EUR],Raw_Data_Combined[GEO],$C35) -> 149085.7
B36: 10 | C36: DE | D36: =COUNTIF(Raw_Data_Combined[GEO],$C36) -> 87 | E36: =COUNTIFS(Raw_Data_Combined[GEO],$C36,Raw_Data_Combined[Status],"Success")/$D36 -> 0.49425287 | F36: =AVERAGEIF(Raw_Data_Combined[GEO],Tasks!C36,Raw_Data_Combined[Gross Amount EUR]) -> 1120.6195 | G36: =AVERAGEIFS(Raw_Data_Combined[Gross Amount EUR],Raw_Data_Combined[GEO],Tasks!$C36,Raw_Data_Combined[Status],"Success") -> 2267.3 | H36: =SUMIFS(Raw_Data_Combined[Net Amount EUR],Raw_Data_Combined[GEO],$C36) -> 95078
B40: Task 4 — Decline Reason Analysis
B42: n/n | C42: Decline Reason | D42: Count | E42: Percentage of Total
B43: 1 | C43: {=_xlfn.UNIQUE(_xlfn._xlws.FILTER(Raw_Data_Combined[Decline Reason], Raw_Data_Combined[Decline Reason]<>""))} -> Card Declined | D43: =COUNTIF(Raw_Data_Combined[Decline Reason],$C43) -> 49 | E43: =$D43/SUM($D$43:$D$47) -> 0.22477064
B44: 2 | C44: Technical Error | D44: =COUNTIF(Raw_Data_Combined[Decline Reason],$C44) -> 44 | E44: =$D44/SUM($D$43:$D$47) -> 0.20183486
B45: 3 | C45: Fraud Suspected | D45: =COUNTIF(Raw_Data_Combined[Decline Reason],$C45) -> 51 | E45: =$D45/SUM($D$43:$D$47) -> 0.23394495
B46: 4 | C46: Insufficient Funds | D46: =COUNTIF(Raw_Data_Combined[Decline Reason],$C46) -> 33 | E46: =$D46/SUM($D$43:$D$47) -> 0.15137615
B47: 5 | C47: Expired Card | D47: =COUNTIF(Raw_Data_Combined[Decline Reason],$C47) -> 41 | E47: =$D47/SUM($D$43:$D$47) -> 0.18807339
B51: Task 5 — Best PSP Provider per GEO (Top 3)
B53: TOP GEO
B54: n/n | C54: TOP GEO
B55: 1 | C55: {=_xlfn.TAKE(_xlfn._xlws.SORT(C27:D36,2,-1),3,1)} -> NL
B56: 2 | C56: GB
B57: 3 | C57: CY
B59: Successful Transaction Rate Per Provider Per GEO
...

Sheet Dashboards
B2: 📊 | C2: PSP Transaction Dashboard · 2024
B4: TOTAL TRANSACTIONS | D4: SUCCESS RATE | F4: TOTAL NET REVENUE | H4: AVG NET (ALL TXN) | J4: AVG SUCCESSFUL TRANSACTION
B5: =COUNTA(Raw_Data_Combined[Transaction ID]) -> 1000 | D5: =COUNTIF(Raw_Data_Combined[Status],"Success")/B5 -> 0.554 | F5: =SUM(Raw_Data_Combined[Net Amount EUR]) -> 1024391.3 | H5: =AVERAGE(Raw_Data_Combined[Net Amount EUR]) -> 1024.3913 | J5: =AVERAGEIFS(Raw_Data_Combined[Net Amount EUR],Raw_Data_Combined[Status],"Success") -> 1849.0818
B6: across all providers | D6: 554 of 1,000 successful | F6: after fees deducted | H6: per transaction incl non-success (net) | J6: per successful transaction (net)
B8: Transaction Status Breakdown | G8: Decline Reason Analysis
B9: Status | C9: Count | D9: % of Total | E9: Bar | G9: Decline Reason | H9: Count | I9: % of Declines | J9: Severity
B10: ✓ Success | C10: =COUNTIF(Raw_Data_Combined[Status],"Success") -> 554 | D10: =C10/SUM($C$10:$C$12) -> 0.554 | E10: =REPT("█",ROUND(D10*30,0)) -> █████████████████ | G10: {=_xlfn.TAKE(_xlfn._xlws.SORT(Tasks!C43:E47,3,-1),,1)} -> Fraud Suspected | H10: =VLOOKUP(G10,Tasks!$C$43:$E$47,2,FALSE) -> 51 | I10: =H10/SUM($H$10:$H$14) -> 0.23394495 | J10: 🔴 High
B11: ⏳ Pending | C11: =COUNTIF(Raw_Data_Combined[Status],"Pending") -> 228 | D11: =C11/SUM($C$10:$C$12) -> 0.228 | E11: =REPT("█",ROUND(D11*30,0)) -> ███████ | G11: Card Declined | H11: =VLOOKUP(G11,Tasks!$C$43:$E$47,2,FALSE) -> 49 | I11: =H11/SUM($H$10:$H$14) -> 0.22477064 | J11: 🟠 Medium
B12: ✗ Failed | C12: =COUNTIF(Raw_Data_Combined[Status],"Failed") -> 218 | D12: =C12/SUM($C$10:$C$12) -> 0.218 | E12: =REPT("█",ROUND(D12*30,0)) -> ███████ | G12: Technical Error | H12: =VLOOKUP(G12,Tasks!$C$43:$E$47,2,FALSE) -> 44 | I12: =H12/SUM($H$10:$H$14) -> 0.20183486 | J12: 🟠 Medium
G13: Expired Card | H13: =VLOOKUP(G13,Tasks!$C$43:$E$47,2,FALSE) -> 41 | I13: =H13/SUM($H$10:$H$14) -> 0.18807339 | J13: 🟡 Low
G14: Insufficient Funds | H14: =VLOOKUP(G14,Tasks!$C$43:$E$47,2,FALSE) -> 33 | I14: =H14/SUM($H$10:$H$14) -> 0.15137615 | J14: 🟡 Low
B15: PSP Provider Performance
B16: Provider | C16: Transactions | D16: Success Rate | E16: Net Revenue | F16: Fees Paid | G16: Fee % | H16: Avg Txn Value | I16: Avg Successful Txn Value
B17: {=_xlfn.TAKE(_xlfn._xlws.SORT(Tasks!C5:E9,3,-1),,1)} -> Checkout.com | C17: =VLOOKUP(Dashboards!B17,Tasks!$C$16:$F$20,4,FALSE) -> 221 | D17: =VLOOKUP(Dashboards!B17,Tasks!$C$5:$F$9,4,FALSE) -> 0.58823529 | E17: =VLOOKUP(Dashboards!B17,Tasks!$C$16:$E$20,2,FALSE) -> 249324.19 | F17: =VLOOKUP(Dashboards!B17,Tasks!$C$16:$E$20,3,FALSE) -> 4828.8748 | G17: =F17/(E17+F17) -> 0.018999868 | H17: =E17/C17 -> 1128.1638 | I17: =AVERAGEIFS(Raw_Data_Combined[Net Amount EUR],Raw_Data_Combined[PSP Provider],$B17,Raw_Data_Combined[Status],"Success") -> 1917.8784
B18: PaySafe | C18: =VLOOKUP(Dashboards!B18,Tasks!$C$16:$F$20,4,FALSE) -> 210 | D18: =VLOOKUP(Dashboards!B18,Tasks!$C$5:$F$9,4,FALSE) -> 0.57142857 | E18: =VLOOKUP(B18,Tasks!$C$16:$E$20,2,FALSE) -> 215751.9 | F18: =VLOOKUP(Dashboards!B18,Tasks!$C$16:$E$20,3,FALSE) -> 7132.3015 | G18: =F18/(E18+F18) -> 0.032000032 | H18: =E18/C18 -> 1027.39 | I18: =AVERAGEIFS(Raw_Data_Combined[Net Amount EUR],Raw_Data_Combined[PSP Provider],$B18,Raw_Data_Combined[Status],"Success") -> 1797.9325
B19: Worldpay | C19: =VLOOKUP(Dashboards!B19,Tasks!$C$16:$F$20,4,FALSE) -> 194 | D19: =VLOOKUP(Dashboards!B19,Tasks!$C$5:$F$9,4,FALSE) -> 0.54123711 | E19: =VLOOKUP(B19,Tasks!$C$16:$E$20,2,FALSE) -> 173586.54 | F19: =VLOOKUP(Dashboards!B19,Tasks!$C$16:$E$20,3,FALSE) -> 4450.9076 | G19: =F19/(E19+F19) -> 0.02499984 | H19: =E19/C19 -> 894.77595 | I19: =AVERAGEIFS(Raw_Data_Combined[Net Amount EUR],Raw_Data_Combined[PSP Provider],$B19,Raw_Data_Combined[Status],"Success") -> 1653.2051
B20: Adyen | C20: =VLOOKUP(Dashboards!B20,Tasks!$C$16:$F$20,4,FALSE) -> 189 | D20: =VLOOKUP(Dashboards!B20,Tasks!$C$5:$F$9,4,FALSE) -> 0.51851852 | E20: =VLOOKUP(B20,Tasks!$C$16:$E$20,2,FALSE) -> 193122.18 | F20: =VLOOKUP(Dashboards!B20,Tasks!$C$16:$E$20,3,FALSE) -> 4142.5884 | G20: =F20/(E20+F20) -> 0.021000143 | H20: =E20/C20 -> 1021.8105 | I20: =AVERAGEIFS(Raw_Data_Combined[Net Amount EUR],Raw_Data_Combined[PSP Provider],$B20,Raw_Data_Combined[Status],"Success") -> 1970.6345
B21: Stripe | C21: =VLOOKUP(Dashboards!B21,Tasks!$C$16:$F$20,4,FALSE) -> 186 | D21: =VLOOKUP(Dashboards!B21,Tasks!$C$5:$F$9,4,FALSE) -> 0.54301075 | E21: =VLOOKUP(B21,Tasks!$C$16:$E$20,2,FALSE) -> 192606.49 | F21: =VLOOKUP(Dashboards!B21,Tasks!$C$16:$E$20,3,FALSE) -> 5752.3726 | G21: =F21/(E21+F21) -> 0.028999827 | H21: =E21/C21 -> 1035.5188 | I21: =AVERAGEIFS(Raw_Data_Combined[Net Amount EUR],Raw_Data_Combined[PSP Provider],$B21,Raw_Data_Combined[Status],"Success") -> 1906.9949
B22: TOTAL | C22: =SUM(C17:C21) -> 1000 | D22: =COUNTIF(Raw_Data_Combined[Status],"Success")/C22 -> 0.554 | E22: =SUM(E17:E21) -> 1024391.3 | F22: =SUM(F17:F21) -> 26307.045 | G22: =F22/(E22+F22) -> 0.025037676 | H22: =E22/C22 -> 1024.3913 | I22: =J5 -> 1849.0818
B25: Monthly Transaction Volume & Revenue
B26: Month | C26: Transactions | D26: Net Revenue | E26: Success Rate
B27: Jan | C27: =COUNTIFS(Raw_Data_Combined[Date & Time],">="&DATE(2024,1,1),Raw_Data_Combined[Date & Time],"<"&DATE(2024,2,1)) -> 73 | D27: =SUMIFS(Raw_Data_Combined[Net Amount EUR],Raw_Data_Combined[Date & Time],">="&DATE(2024,1,1),Raw_Data_Combined[Date & Time],"<"&DATE(2024,2,1)) -> 65638.729 | E27: =COUNTIFS(Raw_Data_Combined[Date & Time],">="&DATE(2024,1,1),Raw_Data_Combined[Date & Time],"<"&DATE(2024,2,1),Raw_Data_Combined[Status],"Success")/C27 -> 0.47945205
B28: Feb | C28: =COUNTIFS(Raw_Data_Combined[Date & Time],">="&DATE(2024,2,1),Raw_Data_Combined[Date & Time],"<"&DATE(2024,3,1)) -> 81 | D28: =SUMIFS(Raw_Data_Combined[Net Amount EUR],Raw_Data_Combined[Date & Time],">="&DATE(2024,2,1),Raw_Data_Combined[Date & Time],"<"&DATE(2024,3,1)) -> 102582.11 | E28: =COUNTIFS(Raw_Data_Combined[Date & Time],">="&DATE(2024,2,1),Raw_Data_Combined[Date & Time],"<"&DATE(2024,3,1),Raw_Data_Combined[Status],"Success")/C28 -> 0.54320988
B29: Mar | C29: =COUNTIFS(Raw_Data_Combined[Date & Time],">="&DATE(2024,3,1),Raw_Data_Combined[Date & Time],"<"&DATE(2024,4,1)) -> 101 | D29: =SUMIFS(Raw_Data_Combined[Net Amount EUR],Raw_Data_Combined[Date & Time],">="&DATE(2024,3,1),Raw_Data_Combined[Date & Time],"<"&DATE(2024,4,1)) -> 70701.008 | E29: =COUNTIFS(Raw_Data_Combined[Date & Time],">="&DATE(2024,3,1),Raw_Data_Combined[Date & Time],"<"&DATE(2024,4,1),Raw_Data_Combined[Status],"Success")/C29 -> 0.48514851
B30: Apr | C30: =COUNTIFS(Raw_Data_Combined[Date & Time],">="&DATE(2024,4,1),Raw_Data_Combined[Date & Time],"<"&DATE(2024,5,1)) -> 75 | D30: =SUMIFS(Raw_Data_Combined[Net Amount EUR],Raw_Data_Combined[Date & Time],">="&DATE(2024,4,1),Raw_Data_Combined[Date & Time],"<"&DATE(2024,5,1)) -> 59781.091 | E30: =COUNTIFS(Raw_Data_Combined[Date & Time],">="&DATE(2024,4,1),Raw_Data_Combined[Date & Time],"<"&DATE(2024,5,1),Raw_Data_Combined[Status],"Success")/C30 -> 0.57333333
B31: May | C31: =COUNTIFS(Raw_Data_Combined[Date & Time],">="&DATE(2024,5,1),Raw_Data_Combined[Date & Time],"<"&DATE(2024,6,1)) -> 84 | D31: =SUMIFS(Raw_Data_Combined[Net Amount EUR],Raw_Data_Combined[Date & Time],">="&DATE(2024,5,1),Raw_Data_Combined[Date & Time],"<"&DATE(2024,6,1)) -> 89803.644 | E31: =COUNTIFS(Raw_Data_Combined[Date & Time],">="&DATE(2024,5,1),Raw_Data_Combined[Date & Time],"<"&DATE(2024,6,1),Raw_Data_Combined[Status],"Success")/C31 -> 0.54761905
B32: Jun | C32: =COUNTIFS(Raw_Data_Combined[Date & Time],">="&DATE(2024,6,1),Raw_Data_Combined[Date & Time],"<"&DATE(2024,7,1)) -> 71 | D32: =SUMIFS(Raw_Data_Combined[Net Amount EUR],Raw_Data_Combined[Date & Time],">="&DATE(2024,6,1),Raw_Data_Combined[Date & Time],"<"&DATE(2024,7,1)) -> 79661.03 | E32: =COUNTIFS(Raw_Data_Combined[Date & Time],">="&DATE(2024,6,1),Raw_Data_Combined[Date & Time],"<"&DATE(2024,7,1),Raw_Data_Combined[Status],"Success")/C32 -> 0.56338028
B33: Jul | C33: =COUNTIFS(Raw_Data_Combined[Date & Time],">="&DATE(2024,7,1),Raw_Data_Combined[Date & Time],"<"&DATE(2024,8,1)) -> 72 | D33: =SUMIFS(Raw_Data_Combined[Net Amount EUR],Raw_Data_Combined[Date & Time],">="&DATE(2024,7,1),Raw_Data_Combined[Date & Time],"<"&DATE(2024,8,1)) -> 66839.333 | E33: =COUNTIFS(Raw_Data_Combined[Date & Time],">="&DATE(2024,7,1),Raw_Data_Combined[Date & Time],"<"&DATE(2024,8,1),Raw_Data_Combined[Status],"Success")/C33 -> 0.47222222
B34: Aug | C34: =COUNTIFS(Raw_Data_Combined[Date & Time],">="&DATE(2024,8,1),Raw_Data_Combined[Date & Time],"<"&DATE(2024,9,1)) -> 97 | D34: =SUMIFS(Raw_Data_Combined[Net Amount EUR],Raw_Data_Combined[Date & Time],">="&DATE(2024,8,1),Raw_Data_Combined[Date & Time],"<"&DATE(2024,9,1)) -> 99286.391 | E34: =COUNTIFS(Raw_Data_Combined[Date & Time],">="&DATE(2024,8,1),Raw_Data_Combined[Date & Time],"<"&DATE(2024,9,1),Raw_Data_Combined[Status],"Success")/C34 -> 0.62886598
B35: Sep | C35: =COUNTIFS(Raw_Data_Combined[Date & Time],">="&DATE(2024,9,1),Raw_Data_Combined[Date & Time],"<"&DATE(2024,10,1)) -> 74 | D35: =SUMIFS(Raw_Data_Combined[Net Amount EUR],Raw_Data_Combined[Date & Time],">="&DATE(2024,9,1),Raw_Data_Combined[Date & Time],"<"&DATE(2024,10,1)) -> 86237.383 | E35: =COUNTIFS(Raw_Data_Combined[Date & Time],">="&DATE(2024,9,1),Raw_Data_Combined[Date & Time],"<"&DATE(2024,10,1),Raw_Data_Combined[Status],"Success")/C35 -> 0.60810811
B36: Oct | C36: =COUNTIFS(Raw_Data_Combined[Date & Time],">="&DATE(2024,10,1),Raw_Data_Combined[Date & Time],"<"&DATE(2024,11,1)) -> 96 | D36: =SUMIFS(Raw_Data_Combined[Net Amount EUR],Raw_Data_Combined[Date & Time],">="&DATE(2024,10,1),Raw_Data_Combined[Date & Time],"<"&DATE(2024,11,1)) -> 122066.1 | E36: =COUNTIFS(Raw_Data_Combined[Date & Time],">="&DATE(2024,10,1),Raw_Data_Combined[Date & Time],"<"&DATE(2024,11,1),Raw_Data_Combined[Status],"Success")/C36 -> 0.61458333
B37: Nov | C37: =COUNTIFS(Raw_Data_Combined[Date & Time],">="&DATE(2024,11,1),Raw_Data_Combined[Date & Time],"<"&DATE(2024,12,1)) -> 76 | D37: =SUMIFS(Raw_Data_Combined[Net Amount EUR],Raw_Data_Combined[Date & Time],">="&DATE(2024,11,1),Raw_Data_Combined[Date & Time],"<"&DATE(2024,12,1)) -> 81808.609 | E37: =COUNTIFS(Raw_Data_Combined[Date & Time],">="&DATE(2024,11,1),Raw_Data_Combined[Date & Time],"<"&DATE(2024,12,1),Raw_Data_Combined[Status],"Success")/C37 -> 0.53947368
B38: Dec | C38: =COUNTIFS(Raw_Data_Combined[Date & Time],">="&DATE(2024,12,1),Raw_Data_Combined[Date & Time],"<"&DATE(2025,1,1)) -> 100 | D38: =SUMIFS(Raw_Data_Combined[Net Amount EUR],Raw_Data_Combined[Date & Time],">="&DATE(2024,12,1),Raw_Data_Combined[Date & Time],"<"&DATE(2025,1,1)) -> 99985.861 | E38: =COUNTIFS(Raw_Data_Combined[Date & Time],">="&DATE(2024,12,1),Raw_Data_Combined[Date & Time],"<"&DATE(2025,1,1),Raw_Data_Combined[Status],"Success")/C38 -> 0.57
B41: GEO Transaction Volume & Revenue | G41: Successful Transaction Rate Per Provider by GEO (TOP 3)
B42: GEO | C42: Transactions | D42: Net Revenue | E42: Success Rate | G42: PSP Provider | H42: Top 3 GEO
B43: {=_xlfn._xlws.SORT(Tasks!C27:D36,2,-1)} -> NL | C43: 125 | D43: =SUMIFS(Raw_Data_Combined[Net Amount EUR],Raw_Data_Combined[GEO], Dashboards!B43) -> 157032.23 | E43: =VLOOKUP(B43,Tasks!$C$27:$E$36,3,FALSE) -> 0.56 | H43: NL | I43: GB | J43: CY
B44: GB | C44: 113 | D44: =SUMIFS(Raw_Data_Combined[Net Amount EUR],Raw_Data_Combined[GEO], Dashboards!B44) -> 161735.55 | E44: =VLOOKUP(B44,Tasks!$C$27:$E$36,3,FALSE) -> 0.51327434 | G44: =Tasks!C61 -> Worldpay | H44: =Tasks!D61 -> 0.44444444 | I44: =Tasks!E61 -> 0.5 | J44: =Tasks!F61 -> 0.47058824
B45: CY | C45: 108 | D45: =SUMIFS(Raw_Data_Combined[Net Amount EUR],Raw_Data_Combined[GEO], Dashboards!B45) -> 149085.7 | E45: =VLOOKUP(B45,Tasks!$C$27:$E$36,3,FALSE) -> 0.56481481 | G45: =Tasks!C62 -> Stripe | H45: =Tasks!D62 -> 0.53571429 | I45: =Tasks!E62 -> 0.47368421 | J45: =Tasks!F62 -> 0.57692308
B46: FR | C46: 101 | D46: =SUMIFS(Raw_Data_Combined[Net Amount EUR],Raw_Data_Combined[GEO], Dashboards!B46) -> 174641.67 | E46: =VLOOKUP(B46,Tasks!$C$27:$E$36,3,FALSE) -> 0.63366337 | G46: =Tasks!C63 -> Checkout.com | H46: =Tasks!D63 -> 0.54545455 | I46: =Tasks!E63 -> 0.65384615 | J46: =Tasks!F63 -> 0.57142857
B47: SE | C47: 100 | D47: =SUMIFS(Raw_Data_Combined[Net Amount EUR],Raw_Data_Combined[GEO], Dashboards!B47) -> 9240.6298 | E47: =VLOOKUP(B47,Tasks!$C$27:$E$36,3,FALSE) -> 0.49 | G47: =Tasks!C64 -> PaySafe | H47: =Tasks!D64 -> 0.62962963 | I47: =Tasks!E64 -> 0.43478261 | J47: =Tasks!F64 -> 0.7
...

Sheet Pivot Tables
A1: REVENUE TREND | J1: TRANSACTION STATUS | P1: GEOGRAPHY | U1: FEES VS REVENUE | Z1: DECLINE ANALYSIS | AD1: PAYMENT METHODS
A3: Sum of Net Amount EUR | B3: Column Labels | J3: Row Labels | K3: Count of Transaction ID | L3: Count of Transaction ID2 | P3: Row Labels | Q3: Sum of Net Amount EUR | R3: Sum of Fee Amount EUR | U3: Row Labels | V3: Sum of Net Amount EUR | W3: Sum of Fee Amount EUR | Z3: Row Labels | AA3: Count of Transaction ID | AD3: Sum of Net Amount EUR | AE3: Column Labels
A4: Row Labels | B4: Adyen | C4: Checkout.com | D4: PaySafe | E4: Stripe | F4: Worldpay | G4: Grand Total | J4: Failed | K4: 0.218 | L4: 218 | P4: CY | Q4: 149085.7 | R4: 3941.84 | U4: Checkout.com | V4: 248501.67 | W4: 4812.9445 | Z4: Card Declined | AA4: 0.22477064 | AD4: Row Labels | AE4: Bank Transfer | AF4: Credit Card | AG4: Crypto | AH4: Debit Card | AI4: E-Wallet | AJ4: Grand Total
A5: January | B5: 15574.31 | C5: 18869.098 | D5: 9562.84 | E5: 7774.4612 | F5: 13840.215 | G5: 65620.924 | J5: Pending | K5: 0.228 | L5: 228 | P5: DE | Q5: 95078 | R5: 2415.9 | U5: PaySafe | V5: 215259.44 | W5: 7116.0222 | Z5: Expired Card | AA5: 0.18807339 | AD5: CY | AE5: 36554.85 | AF5: 19348.26 | AG5: 27807.32 | AH5: 29775.81 | AI5: 35599.46 | AJ5: 149085.7
A6: February | B6: 10240.509 | C6: 18733.817 | D6: 18757.012 | E6: 16302.442 | F6: 37973.004 | G6: 102006.78 | J6: Success | K6: 0.554 | L6: 554 | P6: ES | Q6: 110471.49 | R6: 2994.61 | U6: Adyen | V6: 192481.55 | W6: 4128.847 | Z6: Fraud Suspected | AA6: 0.23394495 | AD6: DE | AE6: 20269.65 | AF6: 8445.67 | AG6: 15982.45 | AH6: 30483.4 | AI6: 19896.83 | AJ6: 95078
A7: March | B7: 17571.851 | C7: 20022.457 | D7: 5377.133 | E7: 20915.745 | F7: 6685.7464 | G7: 70572.932 | J7: Grand Total | K7: 1 | L7: 1000 | P7: FR | Q7: 174641.67 | R7: 4468.82 | U7: Stripe | V7: 192114.78 | W7: 5737.6873 | Z7: Insufficient Funds | AA7: 0.15137615 | AD7: ES | AE7: 26764.37 | AF7: 22899.94 | AG7: 13313.15 | AH7: 24396.28 | AI7: 23097.75 | AJ7: 110471.49
A8: Grand Total | B8: 43386.669 | C8: 57625.372 | D8: 33696.985 | E8: 44992.648 | F8: 58498.966 | G8: 238200.64 | P8: GB | Q8: 157459.88 | R8: 3959.7298 | U8: Worldpay | V8: 172678.72 | W8: 4427.6302 | Z8: Technical Error | AA8: 0.20183486 | AD8: FR | AE8: 27974.7 | AF8: 28161.95 | AG8: 51710.05 | AH8: 30725.79 | AI8: 36069.18 | AJ8: 174641.67
P9: IT | Q9: 120668.87 | R9: 2991.8 | U9: Grand Total | V9: 1021036.2 | W9: 26223.131 | Z9: Grand Total | AA9: 1 | AD9: GB | AE9: 33407.508 | AF9: 7441.6479 | AG9: 36354.084 | AH9: 51073.785 | AI9: 29182.854 | AJ9: 157459.88
J10: Status | K10: Count | L10: % of Total | M10: Bar | P10: NL | Q10: 157032.23 | R10: 3948.28 | AD10: IT | AE10: 28038.18 | AF10: 27945.02 | AG10: 21073.01 | AH10: 15123.32 | AI10: 28489.34 | AJ10: 120668.87
J11: ✓ Success | K11: =GETPIVOTDATA("Count of Transaction ID2",$J$3,"Status","Success") -> 554 | L11: =GETPIVOTDATA("Count of Transaction ID",$J$3,"Status","Success") -> 0.554 | M11: =REPT("█",ROUND(L11*30,0)) -> █████████████████ | P11: NO | Q11: 11471.264 | R11: 283.29171 | AD11: NL | AE11: 27450.79 | AF11: 39927.57 | AG11: 27302.25 | AH11: 36465.89 | AI11: 25885.73 | AJ11: 157032.23
J12: ⏳ Pending | K12: =GETPIVOTDATA("Count of Transaction ID2",$J$3,"Status","Pending") -> 228 | L12: =GETPIVOTDATA("Count of Transaction ID",$J$3,"Status","Pending") -> 0.228 | M12: =REPT("█",ROUND(L12*30,0)) -> ███████ | P12: PL | Q12: 35323.966 | R12: 962.18568 | AD12: NO | AE12: 1363.0141 | AF12: 2808.0473 | AG12: 3363.8074 | AH12: 2379.827 | AI12: 1556.5681 | AJ12: 11471.264
J13: ✗ Failed | K13: =GETPIVOTDATA("Count of Transaction ID2",$J$3,"Status","Failed") -> 218 | L13: =GETPIVOTDATA("Count of Transaction ID",$J$3,"Status","Failed") -> 0.218 | M13: =REPT("█",ROUND(L13*30,0)) -> ███████ | P13: SE | Q13: 9803.1029 | R13: 256.67399 | AD13: PL | AE13: 10994.241 | AF13: 4486.2096 | AG13: 7364.7304 | AH13: 7787.6931 | AI13: 4691.0923 | AJ13: 35323.966
P14: Grand Total | Q14: 1021036.2 | R14: 26223.131 | AD14: SE | AE14: 2609.8631 | AF14: 1432.0242 | AG14: 1464.3056 | AH14: 1586.8416 | AI14: 2710.0684 | AJ14: 9803.1029
AD15: Grand Total | AE15: 215427.17 | AF15: 162896.34 | AG15: 205735.16 | AH15: 229798.64 | AI15: 207178.87 | AJ15: 1021036.2
Q17: Country | R17: Net Revenue (€)
P18: FR | Q18: France | R18: =VLOOKUP(P18,$P$4:$Q$13,2,FALSE) -> 174641.67
P19: NL | Q19: Netherlands | R19: =VLOOKUP(P19,$P$4:$Q$13,2,FALSE) -> 157032.23
P20: PL | Q20: Poland | R20: =VLOOKUP(P20,$P$4:$Q$13,2,FALSE) -> 35323.966
P21: CY | Q21: Cyprus | R21: =VLOOKUP(P21,$P$4:$Q$13,2,FALSE) -> 149085.7
P22: GB | Q22: United Kingdom | R22: =VLOOKUP(P22,$P$4:$Q$13,2,FALSE) -> 157459.88
P23: NO | Q23: Norway | R23: =VLOOKUP(P23,$P$4:$Q$13,2,FALSE) -> 11471.264
P24: IT | Q24: Italy | R24: =VLOOKUP(P24,$P$4:$Q$13,2,FALSE) -> 120668.87
P25: ES | Q25: Spain | R25: =VLOOKUP(P25,$P$4:$Q$13,2,FALSE) -> 110471.49
P26: SE | Q26: Sweden | R26: =VLOOKUP(P26,$P$4:$Q$13,2,FALSE) -> 9803.1029
P27: DE | Q27: Germany | R27: =VLOOKUP(P27,$P$4:$Q$13,2,FALSE) -> 95078

Sheet Dynamic Dashboard
